[2020-04-28 20:34:12,485] 6656-INFO tensorflow_img::__get_model_path():l37: Using file D:\xray_project\sanic_server\ml_modules\models\Pneumonia.h5
[2020-04-28 20:57:03,879] 11348-INFO tensorflow_img::__get_model_path():l35: Using file D:\xray_project\sanic_server\ml_modules\model\*.h5
[2020-04-28 20:57:39,758] 17364-INFO tensorflow_img::__get_model_path():l36: Using file D:\xray_project\sanic_server\ml_modules\model\Pneumonia_87.h5
[2020-04-28 20:57:39,764] 17364-INFO resolver::tfhub_cache_dir():l79: Using C:\Users\CHRIST~1\AppData\Local\Temp\tfhub_modules to cache modules.
[2020-04-28 20:57:54,270] 17364-INFO tensorflow_img::__load_model():l46: Successfully Loaded model
[2020-04-28 20:57:54,271] 17364-INFO app::<module>():l38: Starting localhost development
[2020-04-28 20:57:54,272] 17364-DEBUG app::_helper():l1422: 

                 Sanic
         Build Fast. Run Fast.


[2020-04-28 20:57:54,288] 17364-INFO app::_helper():l1433: Goin' Fast @ http://0.0.0.0:8000
[2020-04-28 20:57:54,289] 17364-DEBUG selector_events::__init__():l53: Using selector: SelectSelector
[2020-04-28 20:57:54,331] 17364-INFO base_events::create_server():l1399: <Server sockets=[<socket.socket fd=1972, family=AddressFamily.AF_INET, type=SocketKind.SOCK_STREAM, proto=6, laddr=('0.0.0.0', 8000)>]> is serving
[2020-04-28 20:57:54,331] 17364-WARNING server::serve():l914: Sanic tried to use loop.add_signal_handler but it is not implemented on this platform.
[2020-04-28 20:57:54,332] 17364-WARNING server::serve():l914: Sanic tried to use loop.add_signal_handler but it is not implemented on this platform.
[2020-04-28 20:57:54,332] 17364-INFO server::serve():l919: Starting worker [17364]
[2020-04-28 21:08:17,117] 17364-INFO base_events::_run_once():l1725: poll took 622782.000 ms: 1 events
[2020-04-28 21:08:17,117] 17364-DEBUG selector_events::_accept_connection():l159: <Server sockets=[<socket.socket fd=1972, family=AddressFamily.AF_INET, type=SocketKind.SOCK_STREAM, proto=6, laddr=('0.0.0.0', 8000)>]> got a new connection from ('127.0.0.1', 51873): <socket.socket fd=448, family=AddressFamily.AF_INET, type=SocketKind.SOCK_STREAM, proto=0, laddr=('127.0.0.1', 8000), raddr=('127.0.0.1', 51873)>
[2020-04-28 21:08:17,133] 17364-DEBUG selector_events::_accept_connection():l159: <Server sockets=[<socket.socket fd=1972, family=AddressFamily.AF_INET, type=SocketKind.SOCK_STREAM, proto=6, laddr=('0.0.0.0', 8000)>]> got a new connection from ('127.0.0.1', 51874): <socket.socket fd=1952, family=AddressFamily.AF_INET, type=SocketKind.SOCK_STREAM, proto=0, laddr=('127.0.0.1', 8000), raddr=('127.0.0.1', 51874)>
[2020-04-28 21:08:17,140] 17364-INFO server::log_response():l465: 
[2020-04-28 21:08:17,368] 17364-DEBUG base_events::_run_once():l1729: poll 5000.000 ms took 235.000 ms: 1 events
[2020-04-28 21:08:17,368] 17364-DEBUG selector_events::_accept_connection():l159: <Server sockets=[<socket.socket fd=1972, family=AddressFamily.AF_INET, type=SocketKind.SOCK_STREAM, proto=6, laddr=('0.0.0.0', 8000)>]> got a new connection from ('127.0.0.1', 51876): <socket.socket fd=1928, family=AddressFamily.AF_INET, type=SocketKind.SOCK_STREAM, proto=0, laddr=('127.0.0.1', 8000), raddr=('127.0.0.1', 51876)>
[2020-04-28 21:08:17,854] 17364-DEBUG base_events::_run_once():l1729: poll 4765.000 ms took 484.000 ms: 1 events
[2020-04-28 21:08:17,855] 17364-ERROR handlers::default():l176: Exception occurred while handling uri: 'http://localhost:8000/favicon.ico'
Traceback (most recent call last):
  File "D:\xray_project\sanic_server\.env\lib\site-packages\sanic\app.py", line 940, in handle_request
    handler, args, kwargs, uri, name = self.router.get(request)
  File "D:\xray_project\sanic_server\.env\lib\site-packages\sanic\router.py", line 411, in get
    return self._get(request.path, request.method, "")
  File "D:\xray_project\sanic_server\.env\lib\site-packages\sanic\router.py", line 475, in _get
    raise NotFound("Requested URL {} not found".format(url))
sanic.exceptions.NotFound: Requested URL /favicon.ico not found
[2020-04-28 21:08:17,869] 17364-INFO server::log_response():l465: 
[2020-04-28 21:08:22,871] 17364-INFO base_events::_run_once():l1733: poll 5000.000 ms took 5000.000 ms: timeout
[2020-04-28 21:08:22,871] 17364-DEBUG server::keep_alive_timeout_callback():l250: KeepAlive Timeout. Closing connection.
[2020-04-28 21:09:17,137] 17364-INFO base_events::_run_once():l1733: poll 54265.000 ms took 54265.000 ms: timeout
[2020-04-28 21:09:17,137] 17364-ERROR handlers::default():l176: Exception occurred while handling uri: unknown
NoneType: None
[2020-04-28 21:09:17,374] 17364-ERROR handlers::default():l176: Exception occurred while handling uri: unknown
NoneType: None
[2020-04-28 21:11:07,335] 17364-INFO base_events::_run_once():l1725: poll took 109968.000 ms: 1 events
[2020-04-28 21:11:07,335] 17364-DEBUG selector_events::_accept_connection():l159: <Server sockets=[<socket.socket fd=1972, family=AddressFamily.AF_INET, type=SocketKind.SOCK_STREAM, proto=6, laddr=('0.0.0.0', 8000)>]> got a new connection from ('127.0.0.1', 51952): <socket.socket fd=1928, family=AddressFamily.AF_INET, type=SocketKind.SOCK_STREAM, proto=0, laddr=('127.0.0.1', 8000), raddr=('127.0.0.1', 51952)>
[2020-04-28 21:11:07,339] 17364-INFO tensorflow_img::__decode_img():l55: Decoding image {img.name}
[2020-04-28 21:11:07,359] 17364-INFO tensorflow_img::predict():l89: Predicting Image {image_file.name}
[2020-04-28 21:11:07,368] 17364-ERROR handlers::default():l176: Exception occurred while handling uri: 'http://localhost:8000/predictImage'
Traceback (most recent call last):
  File "D:\xray_project\sanic_server\.env\lib\site-packages\sanic\app.py", line 974, in handle_request
    response = handler(request, *args, **kwargs)
  File "app.py", line 33, in predict
    retVal = TF.predict(file)
  File "D:\xray_project\sanic_server\ml_modules\tensorflow_img.py", line 92, in predict
    np.expand_dims(decoded_img, axis=0))
  File "D:\xray_project\sanic_server\.env\lib\site-packages\tensorflow_core\python\keras\engine\training.py", line 1013, in predict
    use_multiprocessing=use_multiprocessing)
  File "D:\xray_project\sanic_server\.env\lib\site-packages\tensorflow_core\python\keras\engine\training_v2.py", line 498, in predict
    workers=workers, use_multiprocessing=use_multiprocessing, **kwargs)
  File "D:\xray_project\sanic_server\.env\lib\site-packages\tensorflow_core\python\keras\engine\training_v2.py", line 426, in _model_iteration
    use_multiprocessing=use_multiprocessing)
  File "D:\xray_project\sanic_server\.env\lib\site-packages\tensorflow_core\python\keras\engine\training_v2.py", line 646, in _process_inputs
    x, y, sample_weight=sample_weights)
  File "D:\xray_project\sanic_server\.env\lib\site-packages\tensorflow_core\python\keras\engine\training.py", line 2383, in _standardize_user_data
    batch_size=batch_size)
  File "D:\xray_project\sanic_server\.env\lib\site-packages\tensorflow_core\python\keras\engine\training.py", line 2410, in _standardize_tensors
    exception_prefix='input')
  File "D:\xray_project\sanic_server\.env\lib\site-packages\tensorflow_core\python\keras\engine\training_utils.py", line 582, in standardize_input_data
    str(data_shape))
ValueError: Error when checking input: expected keras_layer_18_input to have shape (224, 224, 3) but got array with shape (128, 128, 3)
[2020-04-28 21:11:07,397] 17364-INFO server::log_response():l465: 
[2020-04-28 21:11:07,431] 17364-DEBUG base_events::_run_once():l1729: poll 5000.000 ms took 15.000 ms: 1 events
[2020-04-28 21:11:07,431] 17364-DEBUG selector_events::_read_ready__on_eof():l823: <_SelectorSocketTransport fd=1928 read=polling write=<idle, bufsize=0>> received EOF
[2020-04-28 21:12:14,973] 17364-INFO server::serve():l922: Stopping worker [17364]
[2020-04-28 21:12:14,975] 17364-DEBUG base_events::close():l602: Close <_WindowsSelectorEventLoop running=False closed=False debug=True>
[2020-04-28 21:12:14,976] 17364-ERROR app::run():l1172: Experienced exception while trying to serve
Traceback (most recent call last):
  File "D:\xray_project\sanic_server\.env\lib\site-packages\sanic\app.py", line 1167, in run
    serve(**server_settings)
  File "D:\xray_project\sanic_server\.env\lib\site-packages\sanic\server.py", line 920, in serve
    loop.run_forever()
  File "D:\development\Anaconda3\lib\asyncio\base_events.py", line 534, in run_forever
    self._run_once()
  File "D:\development\Anaconda3\lib\asyncio\base_events.py", line 1716, in _run_once
    event_list = self._selector.select(timeout)
  File "D:\development\Anaconda3\lib\selectors.py", line 323, in select
    r, w, _ = self._select(self._readers, self._writers, [], timeout)
  File "D:\development\Anaconda3\lib\selectors.py", line 314, in _select
    r, w, x = select.select(r, w, w, timeout)
KeyboardInterrupt
[2020-04-28 21:12:20,326] - INFO tensorflow_img::__get_model_path():l36: Using file D:\xray_project\sanic_server\ml_modules\model\Pneumonia_87.h5
[2020-04-28 21:12:20,332] - INFO resolver::tfhub_cache_dir():l79: Using C:\Users\CHRIST~1\AppData\Local\Temp\tfhub_modules to cache modules.
[2020-04-28 21:12:35,298] - INFO tensorflow_img::__load_model():l46: Successfully Loaded model
[2020-04-28 21:12:35,299] - INFO app::<module>():l38: Starting localhost development
[2020-04-28 21:12:35,300] - DEBUG app::_helper():l1422: 

                 Sanic
         Build Fast. Run Fast.


[2020-04-28 21:12:35,313] - INFO app::_helper():l1433: Goin' Fast @ http://0.0.0.0:8000
[2020-04-28 21:12:35,314] - DEBUG selector_events::__init__():l53: Using selector: SelectSelector
[2020-04-28 21:12:35,320] - INFO base_events::create_server():l1399: <Server sockets=[<socket.socket fd=516, family=AddressFamily.AF_INET, type=SocketKind.SOCK_STREAM, proto=6, laddr=('0.0.0.0', 8000)>]> is serving
[2020-04-28 21:12:35,321] - WARNING server::serve():l914: Sanic tried to use loop.add_signal_handler but it is not implemented on this platform.
[2020-04-28 21:12:35,322] - WARNING server::serve():l914: Sanic tried to use loop.add_signal_handler but it is not implemented on this platform.
[2020-04-28 21:12:35,322] - INFO server::serve():l919: Starting worker [6320]
[2020-04-28 21:12:36,632] - INFO base_events::_run_once():l1725: poll took 1312.000 ms: 1 events
[2020-04-28 21:12:36,632] - DEBUG selector_events::_accept_connection():l159: <Server sockets=[<socket.socket fd=516, family=AddressFamily.AF_INET, type=SocketKind.SOCK_STREAM, proto=6, laddr=('0.0.0.0', 8000)>]> got a new connection from ('127.0.0.1', 51998): <socket.socket fd=1764, family=AddressFamily.AF_INET, type=SocketKind.SOCK_STREAM, proto=0, laddr=('127.0.0.1', 8000), raddr=('127.0.0.1', 51998)>
[2020-04-28 21:12:36,636] - INFO tensorflow_img::__decode_img():l55: Decoding image {img.name}
[2020-04-28 21:12:36,639] - INFO tensorflow_img::predict():l89: Predicting Image {image_file.name}
[2020-04-28 21:12:44,050] - INFO server::log_response():l465: 
[2020-04-28 21:12:44,051] - WARNING base_events::_run_once():l1767: Executing <Task finished coro=<Sanic.handle_request() done, defined at D:\xray_project\sanic_server\.env\lib\site-packages\sanic\app.py:920> result=None created at D:\xray_project\sanic_server\.env\lib\site-packages\sanic\server.py:425> took 7.422 seconds
[2020-04-28 21:12:44,057] - DEBUG base_events::_run_once():l1729: poll 5000.000 ms took 0.000 ms: 1 events
[2020-04-28 21:12:44,057] - DEBUG selector_events::_read_ready__on_eof():l823: <_SelectorSocketTransport fd=1764 read=polling write=<idle, bufsize=0>> received EOF
[2020-04-28 21:18:24,927] - INFO server::serve():l922: Stopping worker [6320]
[2020-04-28 21:18:24,937] - DEBUG base_events::close():l602: Close <_WindowsSelectorEventLoop running=False closed=False debug=True>
[2020-04-28 21:18:24,937] - ERROR app::run():l1172: Experienced exception while trying to serve
Traceback (most recent call last):
  File "D:\xray_project\sanic_server\.env\lib\site-packages\sanic\app.py", line 1167, in run
    serve(**server_settings)
  File "D:\xray_project\sanic_server\.env\lib\site-packages\sanic\server.py", line 920, in serve
    loop.run_forever()
  File "D:\development\Anaconda3\lib\asyncio\base_events.py", line 534, in run_forever
    self._run_once()
  File "D:\development\Anaconda3\lib\asyncio\base_events.py", line 1716, in _run_once
    event_list = self._selector.select(timeout)
  File "D:\development\Anaconda3\lib\selectors.py", line 323, in select
    r, w, _ = self._select(self._readers, self._writers, [], timeout)
  File "D:\development\Anaconda3\lib\selectors.py", line 314, in _select
    r, w, x = select.select(r, w, w, timeout)
KeyboardInterrupt
[2020-04-28 23:25:39,223] - INFO tensorflow_img::__get_model_path():l36: Using file D:\xray_project\sanic_server\ml_modules\models\Pleural_Thickening_0.73.h5
[2020-04-28 23:25:39,226] - INFO resolver::tfhub_cache_dir():l79: Using C:\Users\CHRIST~1\AppData\Local\Temp\tfhub_modules to cache modules.
[2020-04-28 23:25:51,992] - INFO tensorflow_img::_load_model():l46: Successfully Loaded model
[2020-04-28 23:26:43,930] - INFO tensorflow_img::__get_model_path():l36: Using file D:\xray_project\sanic_server\ml_modules\models\Pleural_Thickening_0.73.h5
[2020-04-28 23:26:43,934] - INFO resolver::tfhub_cache_dir():l79: Using C:\Users\CHRIST~1\AppData\Local\Temp\tfhub_modules to cache modules.
[2020-04-28 23:26:56,403] - INFO tensorflow_img::_load_model():l46: Successfully Loaded model
[2020-04-28 23:27:07,522] - INFO tensorflow_img::__get_model_path():l36: Using file D:\xray_project\sanic_server\ml_modules\models\Pleural_Thickening_0.73.h5
[2020-04-28 23:27:07,526] - INFO resolver::tfhub_cache_dir():l79: Using C:\Users\CHRIST~1\AppData\Local\Temp\tfhub_modules to cache modules.
[2020-04-28 23:27:21,591] - INFO tensorflow_img::_load_model():l46: Successfully Loaded model
[2020-04-28 23:28:16,396] - INFO tensorflow_img::__get_model_path():l36: Using file D:\xray_project\sanic_server\ml_modules\models\Pleural_Thickening_0.73.h5
[2020-04-28 23:28:16,400] - INFO resolver::tfhub_cache_dir():l79: Using C:\Users\CHRIST~1\AppData\Local\Temp\tfhub_modules to cache modules.
[2020-04-28 23:28:29,686] - INFO tensorflow_img::_load_model():l46: Successfully Loaded model
[2020-04-28 23:28:52,593] - INFO tensorflow_img::__get_model_path():l36: Using file D:\xray_project\sanic_server\ml_modules\models\Pleural_Thickening_0.73.h5
[2020-04-28 23:28:52,598] - INFO resolver::tfhub_cache_dir():l79: Using C:\Users\CHRIST~1\AppData\Local\Temp\tfhub_modules to cache modules.
[2020-04-28 23:29:05,348] - INFO tensorflow_img::_load_model():l46: Successfully Loaded model
[2020-04-28 23:29:40,098] - INFO tensorflow_img::__get_model_path():l36: Using file D:\xray_project\sanic_server\ml_modules\models\Pleural_Thickening_0.73.h5
[2020-04-28 23:29:40,102] - INFO resolver::tfhub_cache_dir():l79: Using C:\Users\CHRIST~1\AppData\Local\Temp\tfhub_modules to cache modules.
[2020-04-28 23:29:52,864] - INFO tensorflow_img::_load_model():l46: Successfully Loaded model
[2020-04-28 23:30:11,538] - INFO tensorflow_img::__get_model_path():l36: Using file D:\xray_project\sanic_server\ml_modules\models\Pleural_Thickening_0.73.h5
[2020-04-28 23:30:11,541] - INFO resolver::tfhub_cache_dir():l79: Using C:\Users\CHRIST~1\AppData\Local\Temp\tfhub_modules to cache modules.
[2020-04-28 23:32:02,317] - INFO tensorflow_img::__get_model_path():l36: Using file D:\xray_project\sanic_server\ml_modules\models\Pleural_Thickening_0.73.h5
[2020-04-28 23:32:02,321] - INFO resolver::tfhub_cache_dir():l79: Using C:\Users\CHRIST~1\AppData\Local\Temp\tfhub_modules to cache modules.
[2020-04-28 23:32:14,871] - INFO tensorflow_img::_load_model():l46: Successfully Loaded model
[2020-04-28 23:32:27,732] - INFO tensorflow_img::__get_model_path():l36: Using file D:\xray_project\sanic_server\ml_modules\models\Pleural_Thickening_0.73.h5
[2020-04-28 23:32:27,736] - INFO resolver::tfhub_cache_dir():l79: Using C:\Users\CHRIST~1\AppData\Local\Temp\tfhub_modules to cache modules.
[2020-04-28 23:32:40,464] - INFO tensorflow_img::_load_model():l46: Successfully Loaded model
[2020-04-28 23:32:40,469] - INFO tensorflow_img::__decode_img():l55: Decoding image {img.name}
[2020-04-28 23:32:40,482] - INFO tensorflow_img::predict():l90: Predicting Image {image_file.name}
[2020-04-28 23:57:27,652] - INFO tensorflow_img::__get_model_path():l36: Using file D:\xray_project\sanic_server\ml_modules\models\model.h5
[2020-04-28 23:57:27,656] - INFO resolver::tfhub_cache_dir():l79: Using C:\Users\CHRIST~1\AppData\Local\Temp\tfhub_modules to cache modules.
[2020-04-28 23:57:43,805] - INFO tensorflow_img::_load_model():l46: Successfully Loaded model
[2020-04-28 23:57:43,810] - INFO tensorflow_img::__decode_img():l55: Decoding image {img.name}
[2020-04-28 23:57:43,831] - INFO tensorflow_img::predict():l90: Predicting Image {image_file.name}
